Workbook

Sheet Ведомость объёмов работ
A1: № п/п | B1: Наименование работ и формула подсчета | C1: Масса элемента, т | D1: Масса общая, т | E1: Объем элемента, м3 | F1: Общий объем, м3 | G1: Единица, изм. | H1: Количество
A2: Работы нулевого воздуха
A3: А.Земляные работы
A4: 1 | B4: Разработка грунта с перемещением до 10 м бульдозерами мощностью: 59 кВт (80 л.с.), группа грунтов 2 | G4: 1000 м3 | H4: 0.1
A5: 2 | B5: Разработка грунта с погрузкой на автомобили-самосвалы экскаваторами с ковшом вместимостью: 0,4 (0,35-0,45) м3, группа грунтов 2 | G5: 1000 м3 | H5: 0.53
A6: 3 | B6: Разработка грунта вручную в траншеях шириной более 2 м и котлованах площадью сечения до 5 м2 с креплениями, глубина траншей и котлованов: до 3 м, группа грунтов 2 | G6: 1000 м3 | H6: 0.21
A7: Б.Устройство фундаментов и конструкций подвала
A8: 4 | B8: Устройство основания под фундаменты: песчаного | G8: 1 м3 | H8: 15.2
A9: 5 | B9: Укладка блоков и плит ленточных фундаментов при глубине котлована до 4 м, масса конструкций: до 1,5 т. | G9: 100 шт. | H9: 0.16
A10: 5.1 | B10: Укладка блоков и плит ленточных фундаментов при глубине котлована до 4 м, масса конструкций: до 1,5 т. (ФЛ16.8-1) | C10: 0.65 | D10: =0.65*1 -> 0.65 | E10: 0.26 | F10: =0.26*1 -> 0.26 | G10: 100 шт. | H10: 0.01
A11: 5.2 | B11: Укладка блоков и плит ленточных фундаментов при глубине котлована до 4 м, масса конструкций: до 1,5 т. (ФЛ14.12-1) | C11: 1.04 | D11: =1.04*5 -> 5.2 | E11: 0.42 | F11: =0.42*5 -> 2.1 | G11: 100 шт. | H11: 0.05
A12: 5.3 | B12: Укладка блоков и плит ленточных фундаментов при глубине котлована до 4 м, масса конструкций: до 1,5 т.(14.8-1) | C12: 0.685 | D12: =0.685*10 -> 6.85 | E12: 0.27 | F12: =0.27*10 -> 2.7 | G12: 100 шт. | H12: 0.1
A13: 6 | B13: Укладка блоков и плит ленточных фундаментов при глубине котлована до 4 м, масса конструкций: до 3,5 т | G13: 100 шт. | H13: 0.28
A14: 6.1 | B14: Укладка блоков и плит ленточных фундаментов при глубине котлована до 4 м, масса конструкций: до 3,5 т(ФЛ14.24-1) | C14: 2.11 | D14: =C14*12 -> 25.32 | E14: 0.76 | F14: =0.76*12 -> 9.12 | G14: 100 шт. | H14: 0.12
A15: 6.2 | B15: Укладка блоков и плит ленточных фундаментов при глубине котлована до 4 м, масса конструкций: до 3,5 т(ФЛ16.24-1) | C15: 2.15 | D15: =C15*16 -> 34.4 | E15: =0.86 -> 0.86 | F15: =0.85*16 -> 13.6 | G15: 100 шт. | H15: 0.16
A16: 7 | B16: Укладка блоков и плит ленточных фундаментов при глубине котлована до 4 м, масса конструкций: более 3,5 т. | G16: 100 шт. | H16: 0.4
A17: 7.1 | B17: Укладка блоков и плит ленточных фундаментов при глубине котлована до 4 м, масса конструкций: до 1,5 т.(ФБС12.6.6-Т) | C17: 0.96 | D17: =C17*6 -> 5.76 | E17: 0.39 | F17: =E17*6 -> 2.34 | G17: 100 шт. | H17: 0.06
A18: 7.2 | B18: Укладка блоков и плит ленточных фундаментов при глубине котлована до 4 м, масса конструкций: до 1,5 т.(ФБС8.6.6-Т) | C18: 0.78 | D18: =C18*4 -> 3.12 | E18: 0.27 | F18: =E18*4 -> 1.08 | G18: 100 шт. | H18: 0.04
A19: 7.3 | B19: Укладка блоков и плит ленточных фундаментов при глубине котлована до 4 м, масса конструкций: до 1,5 т.(ФБС12.4.6-Т) | C19: 1.18 | D19: =C19*12 -> 14.16 | E19: 0.26 | F19: =E19*12 -> 3.12 | G19: 100 шт. | H19: 0.12
A20: 7.4 | B20: Укладка блоков и плит ленточных фундаментов при глубине котлована до 4 м, масса конструкций: до 1,5 т.(ФБС9.4.6-Т) | C20: 0.88 | D20: =C20*18 -> 15.84 | E20: 0.19 | F20: =E20*18 -> 3.42 | G20: 100 шт. | H20: 0.18
A21: 8 | B21: Укладка блоков и плит ленточных фундаментов при глубине котлована до 4 м, масса конструкций: до 3,5 т. | G21: 100 шт. | H21: 0.54
A22: 8.1 | B22: Укладка блоков и плит ленточных фундаментов при глубине котлована до 4 м, масса конструкций: до 3,5 т.(ФБС24.6.6-Т) | C22: 2.38 | D22: =C22*28 -> 66.64 | E22: 0.81 | F22: =E22*28 -> 22.68 | G22: 100 шт. | H22: 0.28
A23: 8.2 | B23: Укладка блоков и плит ленточных фундаментов при глубине котлована до 4 м, масса конструкций: до 3,5 т.(ФБС24.4.6-Т) | C23: 2.38 | D23: =C23*26 -> 61.88 | E23: 0.54 | F23: =E23*26 -> 14.04 | G23: 100 шт. | H23: 0.26
A24: 9 | B24: Устройство ленточных фундаментов: железобетонных при ширине по верху до 1000 мм(монолитные участки) | G24: 100 м3 | H24: 0.04
A25: 10 | B25: Устройство подстилающих слоев: песчаных | G25: 1 м3 | H25: 10.96
A26: 11 | B26: Устройство подстилающих слоев: бетонных | G26: 1 м3 | H26: 10.96
A27: 12 | B27: Устройство гидроизоляции оклеечной рулонными материалами: на мастике Битуминоль, первый слой | G27: 100 м2 | H27: 0.73
A28: 13 | B28: Устройство тепло- и звукоизоляции сплошной из плит: или матов минераловатных или стекловолокнистых | G28: 100 м2 | H28: 0.73
A29: 14 | B29: Устройство стяжек: цементных толщиной 20 мм | G29: 100 м2 | H29: 2.04
A30: В.Гидроизоляция конструкций подвала и обратная засыпка
A31: 15 | B31: Гидроизоляция боковая обмазочная битумная в 2 слоя по выровненной поверхности бутовой кладки, кирпичу, бетону | G31: 100 м2 | H31: 3.46
A32: 16 | B32: Гидроизоляция стен, фундаментов: горизонтальная оклеечная в 2 слоя | G32: 100 м2 | H32: 0.89
A33: 17 | B33: Засыпка траншей и котлованов с перемещением грунта до 5 м бульдозерами мощностью: 59 кВт (80 л.с.), группа грунтов 2 | G33: 1000 м3 | H33: 0.12
A34: 18 | B34: Уплотнение грунта пневматическими трамбовками, группа грунтов: 1-2 | G34: 100 м3 | H34: 0.05
A35: Работы надземного цикла
A36: Г.Устройство надземной части здания
A37: 19 | B37: Кладка наружных и внутренних кирпичных стен с теплоизоляционными плитами: общей толщиной 510 мм при высоте этажа до 4 м | G37: 1 м3 | H37: 73.4
A38: 20 | B38: Кладка стен кирпичных внутренних: при высоте этажа до 4 м | G38: 1 м3 | H38: 29.29
A39: 21 | B39: Укладка перемычек массой до 0,3 т. | G39: 100 шт. | H39: 0.72
A40: 21.1 | B40: Укладка перемычек массой до 0,3 т.(1ПБ 10-1) | C40: 0.02 | D40: =C40*10 -> 0.2 | E40: 0.008 | F40: =E40*10 -> 0.08 | G40: 100 шт. | H40: 0.1
...

Sheet Локальная смета 
A1: Малоэтажный жилой дом в г.Боровичи
A2: (наименование объекта капитального строительства)
A3: ЛОКАЛЬНЫЙ СМЕТНЫЙ РАСЧЕТ № 19
A4: Малоэтажный жилой дом
A5: (наименование конструктивного решения)
A6: Составлен | D6: базисно-индексным | F6: методом
A7: Основание | D7: Курсовой проект по организации строительного производства
A9: Составлен в текущем (базисном) уровне цен | F9: Ноябрь 2023г. | H9: Январь 2001г.
A10: Сметная стоимость | F10: =R647/1000 -> 12696.963 | H10: =P647/1000 -> 751.5589 | J10: тыс. руб. | O10: Ноябрь 2023 г. | Q10: Январь 2001 г.
B11: в том числе: | M11: Средства на оплату труда рабочих | O11: =(R28+R40+R52+R66+R78+R93+R107+R149+R161+R173+R197+R211+R223+R235+R247+R262+R274+R286+R303+R316+R329+R343+R357+R369+R393+R406+R444+R457+R473+R497+R523+R535+R547+R561+R573+R587+R599+R613++R625+R123+R137+R185+R381+R418+R430+R485+R509+R639)/1000 -> 1285.9934 | Q11: =(P28+P40+P52+P66+P78+P93+P107+P149+P161+P173+P197+P211+P223+P235+P247+P262+P274+P286+P303+P316+P329+P343+P357+P369+P393+P406+P444+P457+P473+P497+P523+P535+P547+P561+P573+P587+P599+P613+P625+P123+P137+P185+P381+P418+P430+P485+P509+P639)/1000 -> 34.059735 | R11: тыс.руб.
B12: строительных работ | F12: =F10 -> 12696.963 | H12: =H10 -> 751.5589 | J12: тыс. руб. | M12: Затраты труда рабочих | O12: =M25+M37+M49+M63+M75+M90+M104+M120+M134+M146+M158+M170+M182+M194+M208+M220+M232+M244+M259+M271+M283+M300+M313+M326+M340+M354+M366+M378+M390+M403+M415+M544+M427+M441+M454+M470+M482+M494+M506+M520+M532+M558+M570+M584+M596+M610+M622+M636 -> 3488.101 | R12: чел.час
B13: монтажных работ | J13: тыс. руб. | M13: Затраты труда машинистов | O13: =M26+M38+M50+M64+M76+M91+M105+M121+M135+M147+M159+M171+M183+M195+M209+M221+M233+M245+M260+M272+M284+M301+M314+M327+M341+M355+M367+M379+M391+M404+M416+M428+M442+M455+M471+M483+M495+M507+M521+M533+M559+M571+M585+M597+M611+M623+M637+M545 -> 200.57841 | R13: маш.час
A15: № п.п. | C15: Обоснование | D15: Наименование работ и затрат | I15: Единица измерения | K15: Количество | N15: Сметная стоимость в базисном уровне цен (в текущем уровне цен (гр. 8) для ресурсов отсутствующих в СНБ), руб. | Q15: Индексы | R15: Сметная стоимость в текущем уровне на цен, руб.
K16: на единицу | L16: коэффициенты | M16: всего с учетом коэффициентов | N16: на единицу | O16: коэффициенты | P16: всего
A17: 1 | C17: 2 | D17: 3 | I17: 4 | K17: 5 | L17: 6 | M17: 7 | N17: 8 | O17: 9 | P17: 10 | Q17: 11 | R17: 12
A18: Работы нулевого цикла
A19: А. Земляные работы
A20: 1 | C20: ФЕР 01-01-030-02 | D20: Разработка грунта с перемещением до 10 м бульдозерами мощностью: 59 кВт (80 л.с.), группа грунтов 2 | I20: 1000 м3 | K20: 0.101 | L20: 1 | M20: =K20 -> 0.101
C21: 1 | D21: ОТ (оплата труда рабочих) | N21: 0 | P21: =M20*N21 -> 0 | Q21: 37.757 | R21: =P21*Q21 -> 0
C22: 3 | D22: ЭМ (эксплуатация машин) | N22: 752.3 | P22: =N22*M20 -> 75.9823 | Q22: 21.128 | R22: =P22*Q22 -> 1605.354
C23: 2 | D23: в т.ч. Отм (оплата труда машинистов) | N23: 146.74 | P23: =N23*M20 -> 14.82074 | Q23: 37.757 | R23: =P23*Q23 -> 559.58668
C24: 4 | D24: М (материалы) | N24: 0 | P24: =N24*M20 -> 0 | Q24: 13.002 | R24: =P24*Q24 -> 0
D25: ЗТ (затраты труда рабочих) | K25: 0 | M25: =K25*M20 -> 0
D26: ЗТ (затраты труда машинистов) | K26: 12.56 | M26: =K26*M20 -> 1.26856
D27: Итого по расценке | P27: =SUM(P21:P24) -> 90.80304 | R27: =SUM(R21:R24) -> 2164.9407
D28: ФОТ (фонд оплаты труда) | P28: =P21+P23 -> 14.82074 | R28: =R21+R23 -> 559.58668
C29: Приказ Минстроя России N°812 | D29: НР (Накладные расходы от ФОТ) | I29: % | K29: 92 | P29: =P28*K29/100 -> 13.635081 | R29: =R28*K29/100 -> 514.81975
C30: Приказ Минстроя России N°774 | D30: СП (Сметная прибыль от ФОТ) | I30: % | K30: 46 | P30: =P28*K30/100 -> 6.8175404 | R30: =R28*K30/100 -> 257.40987
D31: Всего по позиции | P31: =P30+P29+P27 -> 111.25566 | R31: =R30+R29+R27 -> 2937.1703
A32: 2 | C32: ФЕР 01-01-014-02 | D32: Разработка грунта с погрузкой на автомобили-самосвалы экскаваторами с ковшом вместимостью: 0,4 (0,35-0,45) м3, группа грунтов 2 | I32: 1000 м3 | K32: 0.532 | L32: 1 | M32: =K32 -> 0.532
C33: 1 | D33: ОТ (оплата труда рабочих) | N33: 161.93 | P33: =M32*N33 -> 86.14676 | Q33: 37.757 | R33: =P33*Q33 -> 3252.6432
C34: 3 | D34: ЭМ (эксплуатация машин) | N34: 3366.2 | P34: =N34*M32 -> 1790.8184 | Q34: 21.128 | R34: =P34*Q34 -> 37836.411
C35: 2 | D35: в т.ч. Отм (оплата труда машинистов) | N35: 785.61 | P35: =N35*M32 -> 417.94452 | Q35: 37.757 | R35: =P35*Q35 -> 15780.331
C36: 4 | D36: М (материалы) | N36: 4.34 | P36: =N36*M32 -> 2.30888 | Q36: 13.002 | R36: =P36*Q36 -> 30.020058
D37: ЗТ (затраты труда рабочих) | K37: 20.76 | M37: =K37*M32 -> 11.04432
D38: ЗТ (затраты труда машинистов) | K38: 60.2 | M38: =K38*M32 -> 32.0264
D39: Итого по расценке | P39: =SUM(P33:P36) -> 2297.2186 | R39: =SUM(R33:R36) -> 56899.406
D40: ФОТ (фонд оплаты труда) | P40: =P33+P35 -> 504.09128 | R40: =R33+R35 -> 19032.974
C41: Приказ Минстроя России N°812 | D41: НР (Накладные расходы от ФОТ) | I41: % | K41: 92 | P41: =P40*K41/100 -> 463.76398 | R41: =R40*K41/100 -> 17510.337
C42: Приказ Минстроя России N°774 | D42: СП (Сметная прибыль от ФОТ) | I42: % | K42: 46 | P42: =P40*K42/100 -> 231.88199 | R42: =R40*K42/100 -> 8755.1683
...

Sheet Объектная смета
A1: (Наименование стройки)
A2: Малоэтажный жилой дом в г.Боровчичи
A3: (Наименование объекта капитального строительства)
A5: ОБЪЕКТНЫЙ СМЕТНЫЙ РАСЧЕТ (СМЕТА) № ОС -19
A7: Основание | C7: Курсовой проект по организации строительного производства
C8: (проектная и (или) иная техническая документация)
A9: Сметная стоимость | D9: =H40 -> 13474.684 | G9: тыс.руб.
A11: Расчетный измеритель
A12: объекта капитального строительства | D12: 1764.36 | G12: м3
A14: Показатель единичной стоимости
A15: на расчетный измеритель
A16: объекта капитального строительства | D16: =D9/D12 -> 7.6371513 | G16: тыс.руб/м³
A18: Составлен текущем уровне цен | D18: ноябрь | F18: 2023 г.
A20: № п/п | B20: Обоснование | C20: Наименование локальных сметных расчетов (смет), затрат | D20: Сметная стоимость, тыс. руб.
D21: Строительных (ремонтно-строительных, ремонтно-реставрационных) работ | E21: монтажных работ | F21: оборудования, мебели, инвентаря | G21: прочих затрат | H21: Всего
A25: 1 | B25: 2 | C25: 3 | D25: 4 | E25: 5 | F25: 6 | G25: 7 | H25: 8
A26: 1 | B26: ЛС-19 | C26: Локальная смета на общестроительные работы | D26: ='Локальная смета '!R645/1000 -> 10580.803 | H26: =D26 -> 10580.803
A27: 2 | B27: ЛС-СР-19 | C27: Сантехнические работы 1 стадии 12% | E27: =D26*0.12 -> 1269.6963 | H27: =E27 -> 1269.6963
A28: 3 | B28: ЛС-ЭМ-19 | C28: Электромонтажные работы 1 стадии 8% | E28: =D26*0.08 -> 846.46423 | H28: =E28 -> 846.46423
A29: 4 | B29: ЛС-СР-19 | C29: Сантехнические работы 2 стадии 10% | E29: =D26*0.1 -> 1058.0803
A30: 5 | B30: ЛС-ЭМ-19 | C30: Электромонтажные работы 2 стадии 5% | E30: =D26*0.05 -> 529.04014
A31: 6 | B31: ЛС-МО-19 | C31: Монтаж оборудования 0,6% | F31: =D26*0.006 -> 63.484817 | H31: =F31 -> 63.484817
A32: 7 | B32: ЛС-ПО-19 | C32: Приобретение оборудования 1,5% | F32: =D26*0.015 -> 158.71204 | H32: =F32 -> 158.71204
C33: ИТОГО: | D33: =D26 -> 10580.803 | E33: =E27+E28+E29+E30 -> 3703.281 | F33: =F31+F32 -> 222.19686 | G33: 0 | H33: =SUM(H26:H32) -> 12919.16
B34: ГСН 81-05-01-2001 | C34: Временные здания и сооружения 1,1% | D34: =D33*0.011 -> 116.38883 | E34: =E33*0.011 -> 40.736091 | F34: =F33*0.011 -> 2.4441655 | G34: 0 | H34: =H33*0.011 -> 142.11076
C35: ИТОГО: | D35: =D33+D34 -> 10697.192 | E35: =E33+E34 -> 3744.0171 | F35: =F33+F34 -> 224.64103 | G35: =G33+G34 -> 0 | H35: =H33+H34 -> 13061.271
B36: ГСН 81-05-02-2007 табл.4, п.11.2 | C36: Дополнительные затраты на производство работ в зимнее время. зона III 1.2% | D36: =D33*0.012 -> 126.96963 | E36: =E33*0.012 -> 44.439372 | F36: =F33*0.012 -> 2.6663623 | G36: =G33*0.012 -> 0 | H36: =H33*0.012 -> 155.02992
C37: ИТОГО: | D37: =D35+D36 -> 10824.161 | E37: =E35+E36 -> 3788.4565 | F37: =F35+F36 -> 227.30739 | G37: =G35+G36 -> 0 | H37: =H35+H36 -> 13216.301
C38: Непредвиденные затраты 2% | D38: =D33*0.02 -> 211.61606 | E38: =E33*0.02 -> 74.06562 | F38: =F33*0.02 -> 4.4439372 | G38: =G33*0.02 -> 0 | H38: =H33*0.02 -> 258.38321
C39: ИТОГО: | D39: =D37+D38 -> 11035.777 | E39: =E37+E38 -> 3862.5221 | F39: =F37+F38 -> 231.75133 | G39: =G37+G38 -> 0 | H39: =H37+H38 -> 13474.684
C40: ВСЕГО | D40: =D39 -> 11035.777 | E40: =E39 -> 3862.5221 | F40: =F39 -> 231.75133 | G40: =G39 -> 0 | H40: =H39 -> 13474.684
C41: в том числе
C42: ОТ | H42: ='Локальная смета '!O11/1000 -> 1.2859934
C43: ЭМ | H43: =('Локальная смета '!R22+'Локальная смета '!R34+'Локальная смета '!R46+'Локальная смета '!R60+'Локальная смета '!R72+'Локальная смета '!R87+'Локальная смета '!R101+'Локальная смета '!R117+'Локальная смета '!R131+'Локальная смета '!R143+'Локальная смета '!R155++'Локальная смета '!R179+'Локальная смета '!R191+'Локальная смета '!R205+'Локальная смета '!R217+'Локальная смета '!R229+'Локальная смета '!R241+'Локальная смета '!R256+'Локальная смета '!R268+'Локальная смета '!R280+'Локальная смета '!R297+'Локальная смета '!R310+'Локальная смета '!R323+'Локальная смета '!R337+'Локальная смета '!R351+'Локальная смета '!R363+'Локальная смета '!R375+'Локальная смета '!R387+'Локальная смета '!R400+'Локальная смета '!R412+'Локальная смета '!R424+'Локальная смета '!R438+'Локальная смета '!R451+'Локальная смета '!R467+'Локальная смета '!R479+'Локальная смета '!R491+'Локальная смета '!R503+'Локальная смета '!R517+'Локальная смета '!R529+'Локальная смета '!R541+'Локальная смета '!R555+'Локальная смета '!R567+'Локальная смета '!R581+'Локальная смета '!R593+'Локальная смета '!R607+'Локальная смета '!R619+'Локальная смета '!R633)/1000 -> 461.94354
C44: М | H44: =('Локальная смета '!R24+'Локальная смета '!R36+'Локальная смета '!R48+'Локальная смета '!R62+'Локальная смета '!R74+'Локальная смета '!R81+'Локальная смета '!R82+'Локальная смета '!R83+'Локальная смета '!R89+'Локальная смета '!R96+'Локальная смета '!R97+'Локальная смета '!R103+'Локальная смета '!R113+'Локальная смета '!R119+'Локальная смета '!R127+'Локальная смета '!R133+'Локальная смета '!R145+'Локальная смета '!R157+'Локальная смета '!R169+'Локальная смета '!R181+'Локальная смета '!R193+'Локальная смета '!R207+'Локальная смета '!R219+'Локальная смета '!R231+'Локальная смета '!R243+'Локальная смета '!R258+'Локальная смета '!R270+'Локальная смета '!R282+'Локальная смета '!R289+'Локальная смета '!R290+'Локальная смета '!R291+'Локальная смета '!R292+'Локальная смета '!R293+'Локальная смета '!R299+'Локальная смета '!R312+'Локальная смета '!R325+'Локальная смета '!R339+'Локальная смета '!R353+'Локальная смета '!R365+'Локальная смета '!R377+'Локальная смета '!R389+'Локальная смета '!R402+'Локальная смета '!R414+'Локальная смета '!R426+'Локальная смета '!R440+'Локальная смета '!R453+'Локальная смета '!R460+'Локальная смета '!R469+'Локальная смета '!R481+'Локальная смета '!R493+'Локальная смета '!R505+'Локальная смета '!R519+'Локальная смета '!R531+'Локальная смета '!R543+'Локальная смета '!R557+'Локальная смета '!R569+'Локальная смета '!R583+'Локальная смета '!R595+'Локальная смета '!R609+'Локальная смета '!R621+'Локальная смета '!R635+'Локальная смета '!R642+'Локальная смета '!R110+'Локальная смета '!R111+'Локальная смета '!R112+'Локальная смета '!R126)/1000 -> 5865.3819
C45: НР | H45: =('Локальная смета '!R29+'Локальная смета '!R41+'Локальная смета '!R53+'Локальная смета '!R79+'Локальная смета '!R94+'Локальная смета '!R108+'Локальная смета '!R124+'Локальная смета '!R138+'Локальная смета '!R150+'Локальная смета '!R162+'Локальная смета '!R174+'Локальная смета '!R186+'Локальная смета '!R198+'Локальная смета '!R212+'Локальная смета '!R224+'Локальная смета '!R236+'Локальная смета '!R248+'Локальная смета '!R263+'Локальная смета '!R275+'Локальная смета '!R287+'Локальная смета '!R304+'Локальная смета '!R317+'Локальная смета '!R330+'Локальная смета '!R344+'Локальная смета '!R358+'Локальная смета '!R370+'Локальная смета '!R382+'Локальная смета '!R394+'Локальная смета '!R407+'Локальная смета '!R419+'Локальная смета '!R431+'Локальная смета '!R445+'Локальная смета '!R458+'Локальная смета '!R474+'Локальная смета '!R486+'Локальная смета '!R498+'Локальная смета '!R510+'Локальная смета '!R524+'Локальная смета '!R536+'Локальная смета '!R548+'Локальная смета '!R562+'Локальная смета '!R574+'Локальная смета '!R588+'Локальная смета '!R600+'Локальная смета '!R614+'Локальная смета '!R626+'Локальная смета '!R640)/1000 -> 1362.5564
C46: СП | H46: =('Локальная смета '!R30+'Локальная смета '!R42+'Локальная смета '!R54+'Локальная смета '!R68+'Локальная смета '!R80+'Локальная смета '!R95+'Локальная смета '!R109+'Локальная смета '!R125+'Локальная смета '!R139+'Локальная смета '!R151+'Локальная смета '!R163+'Локальная смета '!R175+'Локальная смета '!R187+'Локальная смета '!R199+'Локальная смета '!R213+'Локальная смета '!R225+'Локальная смета '!R237+'Локальная смета '!R249+'Локальная смета '!R264+'Локальная смета '!R276+'Локальная смета '!R288+'Локальная смета '!R305+'Локальная смета '!R318+'Локальная смета '!R331+'Локальная смета '!R345+'Локальная смета '!R359+'Локальная смета '!R383+'Локальная смета '!R395+'Локальная смета '!R408+'Локальная смета '!R395+'Локальная смета '!R408+'Локальная смета '!R420+'Локальная смета '!R432+'Локальная смета '!R446+'Локальная смета '!R459+'Локальная смета '!R475+'Локальная смета '!R487+'Локальная смета '!R499+'Локальная смета '!R511+'Локальная смета '!R525+'Локальная смета '!R537+'Локальная смета '!R549+'Локальная смета '!R563+'Локальная смета '!R575+'Локальная смета '!R589+'Локальная смета '!R601+'Локальная смета '!R615+'Локальная смета '!R627+'Локальная смета '!R641)/1000 -> 810.73244
C47: оборудование | H47: =F40 -> 231.75133
C48: прочие затраты | H48: =G40 -> 0

Sheet Сводный сметный расчет
G1: Форма № 19
A3: Заказчик: | C3: АО "ЛенСПЕЦСМУ"
C4: (наименование организации)
A6: "Утверждён"
A8: Сводный сметный расчёт сметной стоимостью | D8: =H83 -> 38468.446 | E8: тыс.руб.
A11: ссылка на документ об утверждении
A13: СВОДНЫЙ СМЕТНЫЙ РАСЧЁТ СТОИМОСТИ СТРОИТЕЛЬСТВА № ССРСС- 19
A15: Малоэтажный жилой дом в г.Боровичи
A16: (наименование стройки)
A18: Составлен в текущем уровне цен | D18: ноябрь 2023г.
A20: № п/п | B20: Номера сметных расчетов и смет | C20: Наименование глав, объектов, работ и затрат | D20: Сметная стоимость, тыс.руб. | H20: Общая сметная стоимость
D21: строительных работ | E21: монтажных работ | F21: оборудования, мебели, инвентаря | G21: прочих затрат
A24: 1 | B24: 2 | C24: 3 | D24: 4 | E24: 5 | F24: 6 | G24: 7 | H24: 8
A25: Глава 1. Подготовка территории строительства.
A26: 1 | B26: Расчет | C26: Затраты по отводу земельного участка, выдаче архитетурно-планировочного задания и выделению красных линий застройки ( площадь участка 0,1 га стоит 2911* коэффициент перехода в текущие цены для Боровичей 18,737) | G26: =(2911*18.737)/1000 -> 54.543407 | H26: =D26+E26+F26+G26 -> 54.543407
A27: 2 | B27: СНиП 3.01.03-84 УПС-19 | C27: Затраты по разбивке основных осей здания и сооружения, переносу их в натуру и закреплению пунктами и знаками (длина осей здания 131 м* коэффициент перехода в текущие цены для Боровичей 18,737) | G27: =(12779*0.131*18.737)/1000 -> 31.366656 | H27: =D27+E27+F27+G27 -> 31.366656
A28: 3 | B28: Постановление Правительства РФ от 27.11.1995 N 1176 | C28: Плата за землю при изъятии земельного участка для строительства, а так же выплата земельного налога в период строительства | G28: =(1240000*0.1*18.737)/1000 -> 2323.388 | H28: =D28+E28+F28+G28 -> 2323.388
A29: 4 | B29: расчёт | C29: Затраты, связанные с получением заказчиком и проектной организацией исходных данных, технических условий на проектирование и проведение необходимых соглосований по проектным решениям, а также с выполнением по требованию органов местного самоуправления исполнительной контрольной съемки построенных инженерных сетей (0,05%) | G29: =D35*0.05/100 -> 5.2904014 | H29: =SUM(D29:G29) -> 5.2904014
A30: 5 | C30: Затраты, связанные с оплатой работ, выполняемых коммунальными и эксплуатационными организациями, которыенаходятся на полном хозяйственном расчете (кроме организаций, находящихся на бюджетном проектировании), по выдаче исходных данных на проектирование, технических условий и требований на присоединение проектируемых объектов к инженерным сетям и коммуникациям общего пользования, а также затраты на проведение необходимых согласований проектных решений (0,1%) | G30: =D35*0.1/100 -> 10.580803 | H30: =SUM(D30:G30) -> 10.580803
A31: 6 | C31: Затраты на выполнение по требованию органов местного самоуправления контрольной съемки построенных инженерных сетей, а также затраты на выполнение археологических раскопок в пределах строительной площадки (0,1%) | G31: =D35*0.1/100 -> 10.580803 | H31: =SUM(D31:G31) -> 10.580803
A32: 7 | C32: Возмещение собственникам земельных участков, землепользователям, землевладельцам и арендотаров земельных участков убытков, которые причинены изъятием или временным занятием, ораничением прав собственников зумельных участков, землепользователей, землевладельцев и арендоторов земельных участков, либо ухудшением качества земель в результате деятельности других лиц (0,01%) | G32: =D35*0.01/100 -> 1.0580803 | H32: =SUM(D32:G32) -> 1.0580803
C33: Итого по Главе 1 | D33: 0 | E33: 0 | F33: 0 | G33: =SUM(G26:G32) -> 2436.8082 | H33: =SUM(H26:H32) -> 2436.8082
A34: Глава 2. Основные объекты строительства.
A35: 8 | B35: ЛС-19 | C35: Жилой дом | D35: ='Объектная смета'!D33 -> 10580.803 | E35: ='Объектная смета'!E35 -> 3744.0171 | F35: ='Объектная смета'!F33 -> 222.19686 | G35: ='Объектная смета'!G33 -> 0 | H35: =SUM(D35:G35) -> 14547.017
C36: Итого по Главе 2 | D36: =D35 -> 10580.803 | E36: =E35 -> 3744.0171 | F36: =F35 -> 222.19686 | G36: =G35 -> 0 | H36: =H35 -> 14547.017
A37: Глава 3. Объекты подсобного и обслуживающего назначения
A38: 9 | B38: расчет | C38: Строительство мусоросборников, проходных, хозяйственный корпус (3%) | D38: =D35*0.03 -> 317.42409 | E38: =E35*0.03 -> 112.32051 | F38: =F35*0.03 -> 6.6659058 | G38: =G35*0.03 -> 0 | H38: =SUM(D38:G38) -> 436.4105
C39: Итого по Главе 3 | D39: =D38 -> 317.42409 | E39: =E38 -> 112.32051 | F39: =F38 -> 6.6659058 | G39: =G38 -> 0 | H39: =H38 -> 436.4105
A40: Глава 4. Объекты энергетического хозяйства
A41: 10 | B41: расчет | C41: Объекты энергетического хозяйства 2,5% | D41: =D35*0.025 -> 264.52007 | E41: =E35*0.025 -> 93.600427 | F41: =F35*0.025 -> 5.5549215 | G41: =G35*0.025 -> 0 | H41: =SUM(D41:G41) -> 363.67542
C42: Итого по Главе 4 | D42: =D41 -> 264.52007 | E42: =E41 -> 93.600427 | F42: =F41 -> 5.5549215 | G42: =G41 -> 0 | H42: =D42+E42+F42+G42 -> 363.67542
A43: Глава 5. Объекты транспортного хозяйства и связи
A44: 11 | B44: расчет | C44: Объекты транспортного хозяйства и связи 5% | D44: =D35*0.05 -> 529.04014 | E44: =E35*0.05 -> 187.20085 | F44: =F35*0.05 -> 11.109843 | G44: =G35*0.05 -> 0 | H44: =SUM(D44:G44) -> 727.35084
C45: Итого по Главе 5 | D45: =D44 -> 529.04014 | E45: =E44 -> 187.20085 | F45: =F44 -> 11.109843 | G45: =G44 -> 0 | H45: =H44 -> 727.35084
A46: Глава 6. Наружные сети и сооружения водоснабжения, водоотведения, теплоснабжения и газоснабжения
A47: 12 | B47: расчет | C47: Объекты наружной сети 6% | D47: =D35*0.06 -> 634.84817 | E47: =E35*0.06 -> 224.64103 | F47: =F35*0.06 -> 13.331812 | G47: =G35*0.06 -> 0 | H47: =SUM(D47:G47) -> 872.82101
C48: Итого по Главе 6 | D48: =D47 -> 634.84817 | E48: =E47 -> 224.64103 | F48: =F47 -> 13.331812 | G48: =G47 -> 0 | H48: =H47 -> 872.82101
A49: Глава 7. Благоустройство и озеленение
A50: 13 | B50: расчет | C50: Благоустройство и озеленение 8% | D50: =D35*0.08 -> 846.46423 | E50: =E35*0.08 -> 299.52137 | F50: =F35*0.08 -> 17.775749 | G50: =G35*0.08 -> 0 | H50: =SUM(D50:G50) -> 1163.7613
C51: Итого по Главе 7 | D51: =D50 -> 846.46423 | E51: =E50 -> 299.52137 | F51: =F50 -> 17.775749 | G51: =G50 -> 0 | H51: =H50 -> 1163.7613
...

Sheet Ресурсная ведомость трудозатрат
A1: Основание: | B1: Курсовой проект по организации строительного производства
A3: № п/п по смете | B3: Шифр номера нормативов и ресурсов | C3: Наименование работ и затрат | D3: Индекс к заработной плате | E3: Ед.изм. | F3: Количество трудозатрат | G3: Стоимость единицы, руб | H3: Стоимость общая, руб
A4: 1 | B4: 2 | C4: 3 | D4: 4 | E4: 5 | F4: 6 | G4: 7 | H4: 8
C5: Трудовые ресурсы
A6: 2 | B6: ФЕР 01-01-014-02 | C6: Трудозатраты рабочих 2 разряда | D6: 37.76 | E6: чел.-ч | F6: 11.04 | G6: 9.53 | H6: =D6*F6*G6 -> 3972.7749
A7: 3 | B7: ФЕР 01-02-057-02 | C7: Трудозатраты рабочих 2 разряда | D7: 37.76 | E7: чел.-ч | F7: 32.34 | G7: 9.53 | H7: =D7*F7*G7 -> 11637.64
A8: 4 | B8: ФЕР 08-01-002-01 | C8: Трудозатраты рабочих 2,5 разряда | D8: 37.76 | E8: чел.-ч | F8: 34.96 | G8: 9.98 | H8: =D8*F8*G8 -> 13174.494
A9: 5 | B9: ФЕР 07-01-001-02 | C9: Трудозатраты рабочих 3,3 разряда | D9: 37.76 | E9: чел.-ч | F9: 14.6 | G9: 10.83 | H9: =D9*F9*G9 -> 5970.5357
A10: 6 | B10: ФЕР 07-01-001-03 | C10: Трудозатраты рабочих 3,5 разряда | D10: 37.76 | E10: чел.-ч | F10: 37.61 | G10: 11.1 | H10: =D10*F10*G10 -> 15763.705
A11: 7 | B11: ФЕР 07-01-001-02 | C11: Трудозатраты рабочих 3,3 разряда | D11: 37.76 | E11: чел.-ч | F11: 23.81 | G11: 10.83 | H11: =D11*F11*G11 -> 9736.8804
A12: 8 | B12: ФЕР 07-01-001-03 | C12: Трудозатраты рабочих 3,5 разряда | D12: 37.76 | E12: чел.-ч | F12: 37.61 | G12: 11.1 | H12: =D12*F12*G12 -> 15763.705
A13: 9 | B13: ФЕР 06-01-001-22 | C13: Трудозатраты рабочих 3,3 разряда | D13: 37.76 | E13: чел.-ч | F13: 16.95 | G13: 10.83 | H13: =D13*F13*G13 -> 6931.5466
A14: 10 | B14: ФЕР 11-01-002-01 | C14: Трудозатраты рабочих 3,1 разряда | D14: 37.76 | E14: чел.-ч | F14: 37.37 | G14: 10.56 | H14: =D14*F14*G14 -> 14901.123
A15: 11 | B15: ФЕР 11-01-002-09 | C15: Трудозатраты рабочих 2,8 разряда | D15: 37.76 | E15: чел.-ч | F15: 40.11 | G15: 10.25 | H15: =D15*F15*G15 -> 15524.174
A16: 12 | B16: ФЕР 11-01-004-01 | C16: Трудозатраты рабочих 5,1 разряда | D16: 37.76 | E16: чел.-ч | F16: 33.71 | G16: 13.78 | H16: =D16*F16*G16 -> 17540.419
A17: 13 | B17: ФЕР 11-01-009-01 | C17: Трудозатраты рабочих 3,4 разряда | D17: 37.76 | E17: чел.-ч | F17: 20.72 | G17: 10.97 | H17: =D17*F17*G17 -> 8582.7876
... A51: 48 | B51: ФЕР 15-01-080-04 | C51: Трудозатраты рабочих 3,4 разряда | D51: 37.76 | E51: чел.-ч | F51: 444.07 | G51: 10.97 | H51: =D51*F51*G51 -> 183945.87
C52: ИТОГО по зарплате рабочих | F52: =SUM(F6:F51) -> 3488.05 | H52: =SUM(H6:H51) -> 1447092.7
C53: Затраты труда машинистов
A54: 1 | B54: ФЕР 01-01-030-02 | C54: Трудозатраты машинистов 5 разряда | D54: 37.76 | E54: чел.-ч | F54: 1.27 | G54: 13.56 | H54: =D54*F54*G54 -> 650.27251
A55: 2 | B55: ФЕР 01-01-014-02 | C55: Трудозатраты машинистов 6 разряда | D55: 37.76 | E55: чел.-ч | F55: 32.03 | G55: 15.8 | H55: =D55*F55*G55 -> 19109.354
A56: 4 | B56: ФЕР 08-01-002-01 | C56: Трудозатраты машинистов 6 разряда | D56: 37.76 | E56: чел.-ч | F56: 4.41 | G56: 15.8 | H56: =D56*F56*G56 -> 2631.0413
A57: 5 | B57: ФЕР 07-01-001-02 | C57: Трудозатраты машинистов 6 разряда | D57: 37.76 | E57: чел.-ч | F57: 5 | G57: 15.8 | H57: =D57*F57*G57 -> 2983.04
A58: 6 | B58: ФЕР 07-01-001-03 | C58: Трудозатраты машинистов 6 разряда | D58: 37.76 | E58: чел.-ч | F58: 12.27 | G58: 15.8 | H58: =D58*F58*G58 -> 7320.3802
A59: 7 | B59: ФЕР 07-01-001-02 | C59: Трудозатраты машинистов 6 разряда | D59: 37.76 | E59: чел.-ч | F59: 8.13 | G59: 15.8 | H59: =D59*F59*G59 -> 4850.423
A60: 8 | B60: ФЕР 07-01-001-03 | C60: Трудозатраты машинистов 6 разряда | D60: 37.76 | E60: чел.-ч | F60: 12.27 | G60: 15.8 | H60: =D60*F60*G60 -> 7320.3802
A61: 9 | B61: ФЕР 06-01-001-22 | C61: Трудозатраты машинистов 6 разряда | D61: 37.76 | E61: чел.-ч | F61: 1.09 | G61: 15.8 | H61: =D61*F61*G61 -> 650.30272
A62: 10 | B62: ФЕР 11-01-002-01 | C62: Трудозатраты машинистов 6 разряда | D62: 37.76 | E62: чел.-ч | F62: 3.29 | G62: 15.8 | H62: =D62*F62*G62 -> 1962.8403
A63: 12 | B63: ФЕР 11-01-004-01 | C63: Трудозатраты машинистов 6 разряда | D63: 37.76 | E63: чел.-ч | F63: 0.28 | G63: 15.8 | H63: =D63*F63*G63 -> 167.05024
A64: 13 | B64: ФЕР 11-01-009-01 | C64: Трудозатраты машинистов 6 разряда | D64: 37.76 | E64: чел.-ч | F64: 0.13 | G64: 15.8 | H64: =D64*F64*G64 -> 77.55904
A65: 14 | B65: ФЕР 11-01-011-01 | C65: Трудозатраты машинистов 6 разряда | D65: 37.76 | E65: чел.-ч | F65: 2.59 | G65: 15.8 | H65: =D65*F65*G65 -> 1545.2147
... A94: 48 | B94: ФЕР 15-01-080-04 | C94: Трудозатраты машинистов 6 разряда | D94: 37.76 | E94: чел.-ч | F94: 26.62 | G94: 15.8 | H94: =D94*F94*G94 -> 15881.705
C95: ИТОГО по зарплате машинистов | F95: =SUM(F54:F94) -> 200.62 | H95: =SUM(H54:H94) -> 119463.86
C96: ИТОГО ФОТ | F96: =F52+F95 -> 3688.67 | H96: =H52+H95 -> 1566556.5

Sheet Расчёт состава бригад
B1: Общая трудоемкость, чел.-ч | C1: В т.ч. разряды
C2: 2 | D2: 3 | E2: 4 | F2: 5 | G2: 6
A3: Рабочие | B3: 3488.05 | C3: 288.38 | D3: 1810.24 | E3: 1355.72 | F3: 33.7 | G3: ='Ресурсная ведомость трудозатрат'!N5 -> 0
A4: Машинисты | B4: 200.62 | C4: ='Ресурсная ведомость трудозатрат'!J6 -> 0 | D4: ='Ресурсная ведомость трудозатрат'!K6 -> 0 | E4: 0.79 | F4: 1.27 | G4: 198.6
A5: ИТОГО | B5: 3688.67 | C5: =C3+C4 -> 288.38 | D5: =D3+D4 -> 1810.24 | E5: =E3+E4 -> 1356.51 | F5: =F3+F4 -> 34.97 | G5: =G3+G4 -> 198.6
A7: Определяем количество рабочих по формуле: | O7: 2 разряд | P7: 1.5-2,4
A8: n= Тр/(Дк*8) | B8: n= Тр/(Дк*8) | O8: 3 разряд | P8: 2,5-3,4
A9: n=3688,67/90*8= | B9: =B5/(90*8) -> 5.1231528 | C9: чел. | O9: 4 разряд | P9: 3,5-4,4
A10: Принимаем бригаду из | B10: 6 | C10: чел. | O10: 5 разряд | P10: 4,5-5,4
A11: Тр – общие трудозатраты, чел.*ч | O11: 6 разряд | P11: 5,5-6,4
A12: Дк – количество дней по календарному плану, дн
A13: Определяем состав бригады по разрядам рабочих: | E13: Принимаем
A14: 2 разряд = (288,37*6)/3688,67= | C14: =C5*B10/B5 -> 0.46907964 | D14: чел. | E14: 2 | F14: чел.
A15: 3 разряд = (1810,24*6)/3688,67= | C15: =D5*B10/B5 -> 2.944541 | D15: чел. | E15: 2 | F15: чел.
A16: 4 разряд = (1356,51*6)/3688,67= | C16: =E5*B10/B5 -> 2.2065026 | D16: чел. | E16: 2 | F16: чел.
A18: Расчет правильности выбора состава бригады
A19: Определяем средний разряд рабочих:
A20: Рср=(1*2+3*3+2*4)/6= | C20: =(2*2+2*3+2*4)/6 -> 3
A21: Определяем средний разряд работ:
A22: Средний разряд работ можно определить с помощью средней часовой ставки работ, которая определяется по формуле:
A23: Тст.ч = Рсд/Тр;
A24: Тст.ч – средняя часовая тарифная ставка;
A25: Рсд – сдельная расценка, руб;
A26: Тр – общая трудоемкость, чел.*ч;
A27: Тст.ч = 1447092,66/3688,67= | B27: ='Ресурсная ведомость трудозатрат'!H52/'Расчёт состава бригад'!B5 -> 392.30743 | C27: руб.
A28: Сравниваем полученные значения со стоимостью 1 чел.*ч рабочих, занятых в строительстве на строительно-монтажных работах с нормальными условиями труда, установленными нормой:
A29: 37,76– индекс к заработной плате
A30: 392,31/37,76= | B30: =B27/37.76 -> 10.389498 | C30: руб/ч,
A31: что соответствует разряду работ 3,0
A32: Вывод: состав бригады выбран правильно, т.к. средний разряд рабочих соответствует среднему разряду работ (отклонение до 0,1÷0,3).

Sheet Фонд оплаты труда
A1: Расчет фонда оплаты труда (ФОТ) и средней заработной платы
A3: № | B3: Наименование показателей | C3: Ед.изм | D3: Значение показателей | E3: Примеч.
A4: 1 | B4: Сдельная з/пл рабочих (всего) | C4: Руб. | D4: ='Ресурсная ведомость трудозатрат'!H52 -> 1447092.7 | E4: Ресурсная ведомость
A5: 2 | B5: Трудоемкость рабочих | C5: Чел.-ч | D5: ='Ресурсная ведомость трудозатрат'!F52 -> 3488.05 | E5: Ресурсная ведомость
A6: 3 | B6: Средняя часовая тарифная ставка рабочего | C6: Руб. | D6: =D4/D5 -> 414.87154 | E6: П.1/ п.2
A7: 4 | B7: Среднедневная з/пл рабочего | C7: Руб. | D7: =D6*8 -> 3318.9723 | E7: П.3*8ч
A8: 5 | B8: Среднемесячная з/пл рабочего | C8: Руб. | D8: =D7*22 -> 73017.39 | E8: П.4*22 дня
A9: 6 | B9: Заработная плата машинистов (всего) | C9: Руб. | D9: ='Ресурсная ведомость трудозатрат'!H95 -> 119463.86 | E9: Ресурсная ведомость
A10: 7 | B10: Трудоемкость машинистов | C10: Чел.-ч | D10: ='Ресурсная ведомость трудозатрат'!F95 -> 200.62 | E10: Ресурсная ведомость
A11: 8 | B11: Средняя часовая тарифная ставка машиниста | C11: Руб. | D11: =D9/D10 -> 595.47334 | E11: П.6/ п.7
A12: 9 | B12: Среднедневная з/пл машиниста | C12: Руб. | D12: =D11*8 -> 4763.7867 | E12: П.8*8ч
A13: 10 | B13: Среднемесячная з/пл машиниста | C13: Руб. | D13: =D12*22 -> 104803.31 | E13: П.9*22 дня

Sheet Прибыль и затраты
A1: Расчет затрат, прибыли и рентабельности строительства
A3: № | B3: Наименование показателей | C3: Значение показателей, руб. | D3: Примеч.
A4: 1 | B4: Материалы | C4: ='Объектная смета'!H44*1000 -> 5865381.9 | D4: Объектная смета
A5: 2 | B5: Машины и механизмы | C5: ='Объектная смета'!H43*1000 -> 461943.54 | D5: Объектная смета
A6: 3 | B6: Фонд оплаты труда | C6: ='Ресурсная ведомость трудозатрат'!H96 -> 1566556.5 | D6: Локальная смета (или ресурсная ведомость)
A7: 4 | B7: ИТОГО прямых затрат: | C7: =C4+C5+C6 -> 7893882
A8: 5 | B8: Накладные расходы | C8: ='Объектная смета'!H45*1000 -> 1362556.4 | D8: Объектная смета
A9: 6 | B9: Себестоимость строительно-монтажных работ | C9: =('Объектная смета'!H42+'Объектная смета'!H43+'Объектная смета'!H44+'Объектная смета'!H45)*1000 -> 7691167.8 | D9: ПЗ+НР
A10: 7 | B10: Договорная цена без НДС | C10: =C9*1.047 -> 8052652.7 | D10: Ссмр* индекс-дефлятор
A11: 8 | B11: Плановая прибыль | C11: =C10-C9 -> 361484.89 | D11: Сдог – Ссеб
A12: 9 | B12: Плановая рентабельность | C12: =(C11*100)/C9 -> 4.7 | D12: Ппл*100/Ссеб
A13: 10 | B13: Сметная прибыль | C13: ='Объектная смета'!H46*1000 -> 810732.44 | D13: Объектная смета
A14: 11 | B14: Сметная рентабельность | C14: =C13*100/C9 -> 10.541084 | D14: СП*100/Сстр

Sheet ТЭП
A1: Технико–экономические показатели проекта
A3: № п/п | B3: Наименование показателей | C3: Ед.изм | D3: Значение показателей | E3: Примечание
A4: 1 | B4: 2 | C4: 3 | D4: 4 | E4: 5
A5: 1. Объемно-планировочные показатели
A6: 1.1 | B6: Этажность | C6: Эт. | D6: 2 | E6: По проекту
A7: 1.2 | B7: Строительный объем | C7: м³ | D7: 1260.24 | E7: По проекту
A8: 1.3 | B8: Площадь застройки | C8: м² | D8: 154 | E8: По проекту
A9: 1.4 | B9: Жилая площадь | C9: м² | D9: 98.4 | E9: По проекту
A10: 2. Показатели сметной стоимости строительства
A11: 2.1 | B11: Сметная стоимость строительства объекта | C11: Тыс.р | D11: ='Сводный сметный расчет'!D8 -> 38468.446 | E11: Сводный сметный расчет
A12: 2.2 | B12: Сметная стоимость общестроительных работ | C12: Тыс.р. | D12: ='Локальная смета '!F12 -> 12696.963 | E12: Локальная смета
A13: 2.3 | B13: Сметная стоимость 1 м³ | C13: Тыс.р | D13: =D12/D7 -> 10.075036 | E13: Смет.ст-ть/ Vстр
A14: 2.4 | B14: Сметная стоимость 1 м² жилой площади | C14: Тыс.р | D14: =D12/D9 -> 129.03418 | E14: Смет.ст-ть/ Fж
A15: 2.5 | B15: Прибыль | C15: руб. | D15: ='Объектная смета'!H46*1000 -> 810732.44
A16: 2.6 | B16: Уровень рентабельности | C16: % | D16: =D15*100/D18 -> 10.541084 | E16: Приб.*100/Ссеб.
A17: 2.7 | B17: Договорная цена | C17: руб. | D17: =D12*1.047*1000 -> 13293721 | E17: Локальная смета * Индекс-дефлятор
A18: 2.8 | B18: Себестоимость | C18: руб. | D18: =('Объектная смета'!H42+'Объектная смета'!H43+'Объектная смета'!H44+'Объектная смета'!H45)*1000 -> 7691167.8 | E18: ПЗ+НР
A19: 3. Показатели трудовых затрат
A20: 3.1 | B20: Трудозатраты по объекту в целом | C20: Чел.-дн | D20: =D21*112.5/100 -> 4149.7643 | E20: ЛС
A21: 3.2 | B21: Трудозатраты на общестроительные работы | C21: Чел.-дн | D21: ='Локальная смета '!O12+'Локальная смета '!O13 -> 3688.6794 | E21: Локальная смета
A22: 3.3 | B22: Затраты труда на 1 м² общей площади | C22: Чел.-дн | D22: =D20/D7 -> 3.2928365 | E22: Поз.3.1/поз.1.2
A23: 3.4 | B23: Выработка рабочих за смену | C23: Руб./ Чел.-дн | D23: =(D12/D21)*1000 -> 3442.1434 | E23: (Поз.2.2/поз.3.2)*1000
A24: 4. Показатели технологичности проекта
A25: 4.1 | B25: Нормативная продолжительность строительства | C25: дн | D25: 165 | E25: СНиП 1.04.03-85* Раздел А.
A26: 4.2 | B26: Плановая продолжительность строительства* | C26: дн | D26: 90 | E26: По проекту (* не должна превышать нормативную)
